[2024-06-30 08:24:55,317] {taskinstance.py:896} INFO - Dependencies all met for <TaskInstance: assignment.task_one 2024-06-29T00:00:00+00:00 [queued]>
[2024-06-30 08:24:55,328] {taskinstance.py:896} INFO - Dependencies all met for <TaskInstance: assignment.task_one 2024-06-29T00:00:00+00:00 [queued]>
[2024-06-30 08:24:55,328] {taskinstance.py:1087} INFO - 
--------------------------------------------------------------------------------
[2024-06-30 08:24:55,329] {taskinstance.py:1088} INFO - Starting attempt 5 of 5
[2024-06-30 08:24:55,329] {taskinstance.py:1089} INFO - 
--------------------------------------------------------------------------------
[2024-06-30 08:24:55,343] {taskinstance.py:1107} INFO - Executing <Task(PythonOperator): task_one> on 2024-06-29T00:00:00+00:00
[2024-06-30 08:24:55,346] {standard_task_runner.py:52} INFO - Started process 3509 to run task
[2024-06-30 08:24:55,349] {standard_task_runner.py:76} INFO - Running: ['***', 'tasks', 'run', 'assignment', 'task_one', '2024-06-29T00:00:00+00:00', '--job-id', '11', '--pool', 'default_pool', '--raw', '--subdir', 'DAGS_FOLDER/assignment.py', '--cfg-path', '/tmp/tmpocmyiml3', '--error-file', '/tmp/tmpi9ld1hq9']
[2024-06-30 08:24:55,350] {standard_task_runner.py:77} INFO - Job 11: Subtask task_one
[2024-06-30 08:24:55,382] {logging_mixin.py:104} INFO - Running <TaskInstance: assignment.task_one 2024-06-29T00:00:00+00:00 [running]> on host 2532fdaf14cb
[2024-06-30 08:24:55,421] {taskinstance.py:1302} INFO - Exporting the following env vars:
AIRFLOW_CTX_DAG_OWNER=***
AIRFLOW_CTX_DAG_ID=assignment
AIRFLOW_CTX_TASK_ID=task_one
AIRFLOW_CTX_EXECUTION_DATE=2024-06-29T00:00:00+00:00
AIRFLOW_CTX_DAG_RUN_ID=scheduled__2024-06-29T00:00:00+00:00
[2024-06-30 08:24:56,095] {logging_mixin.py:104} INFO - wrote file: m1a.html
[2024-06-30 08:24:56,095] {logging_mixin.py:104} INFO - pulled: m1a.html
[2024-06-30 08:24:56,095] {logging_mixin.py:104} INFO - --- waiting ---
[2024-06-30 08:25:00,399] {local_task_job.py:199} WARNING - State of this instance has been externally set to shutdown. Terminating instance.
[2024-06-30 08:25:00,401] {process_utils.py:100} INFO - Sending Signals.SIGTERM to GPID 3509
[2024-06-30 08:25:00,401] {taskinstance.py:1284} ERROR - Received SIGTERM. Terminating subprocesses.
[2024-06-30 08:25:00,408] {taskinstance.py:1501} ERROR - Task failed with exception
Traceback (most recent call last):
  File "/home/airflow/.local/lib/python3.6/site-packages/airflow/models/taskinstance.py", line 1157, in _run_raw_task
    self._prepare_and_execute_task_with_callbacks(context, task)
  File "/home/airflow/.local/lib/python3.6/site-packages/airflow/models/taskinstance.py", line 1331, in _prepare_and_execute_task_with_callbacks
    result = self._execute_task(context, task_copy)
  File "/home/airflow/.local/lib/python3.6/site-packages/airflow/models/taskinstance.py", line 1361, in _execute_task
    result = task_copy.execute(context=context)
  File "/home/airflow/.local/lib/python3.6/site-packages/airflow/operators/python.py", line 150, in execute
    return_value = self.execute_callable()
  File "/home/airflow/.local/lib/python3.6/site-packages/airflow/operators/python.py", line 161, in execute_callable
    return self.python_callable(*self.op_args, **self.op_kwargs)
  File "/opt/airflow/dags/assignment.py", line 85, in catalog
    time.sleep(15)
  File "/home/airflow/.local/lib/python3.6/site-packages/airflow/models/taskinstance.py", line 1286, in signal_handler
    raise AirflowException("Task received SIGTERM signal")
airflow.exceptions.AirflowException: Task received SIGTERM signal
[2024-06-30 08:25:00,413] {taskinstance.py:1551} INFO - Marking task as FAILED. dag_id=assignment, task_id=task_one, execution_date=20240629T000000, start_date=20240630T082455, end_date=20240630T082500
[2024-06-30 08:25:00,453] {process_utils.py:66} INFO - Process psutil.Process(pid=3509, status='terminated', exitcode=1, started='08:24:54') (3509) terminated with exit code 1
